<?xml version="1.0" ?>
  <robot name="explorer">
  <link name="base_footprint">
    <visual>
      <geometry>
          <box size="0.75 0.4 0.1"/>
      </geometry>
      <material name="gray">
        <color rgba=".2 .2 .2 1" />
      </material>
    </visual>
  <inertial>
            <mass value="1" />
            <inertia ixx="0.01" ixy="0.0" ixz="0" 
            iyy="0.01" iyz="0" izz="0.01" />
    </inertial>
    <collision>
      <geometry>
          <box size="0.75 0.4 0.1"/>
      </geometry>
      
    </collision>
  </link>

  <link name="wheel_right_link">
    <inertial>
            <mass value="2" />
            <inertia ixx="0.01" ixy="0.0" ixz="0" 
            iyy="0.01" iyz="0" izz="0.01" />
    </inertial>

    <visual>
      
      <geometry>
          <cylinder radius="0.15" length="0.1"/>
      </geometry>
      <material name="white">
        <color rgba="1 1 1 1"/>
      </material>
    </visual>

    <collision>
    
      <geometry>
          <cylinder radius="0.15" length="0.1"/>
      </geometry>
      <surface>
        <friction>
          <ode>
            <mu>0</mu>
            <mu2>0</mu2>
            <slip1>1.0</slip1>
            <slip2>1.0</slip2>
          </ode>
        </friction>
      </surface>
      <contact_coefficients mu="1" kp="1e+13" kd="1.0"/>
    </collision>
  </link>

  <joint name="wheel_right_joint" type="continuous">
    <origin xyz="0.2 0.25 0.0" rpy="1.57 0.0 0.0"/>
    <parent link="base_footprint"/>
    <child link="wheel_right_link"/>
    <axis xyz="0.0 0.0 1.0"/>
  </joint>

  <link name="wheel_left_link">
    <inertial>
            <mass value="2" />
            <inertia ixx="0.01" ixy="0.0" ixz="0" 
            iyy="0.01" iyz="0" izz="0.01" />
    </inertial>

    <visual>
      
      <geometry>
          <cylinder radius="0.15" length="0.1"/>
      </geometry>
      <material name="white">
        <color rgba="1 1 1 1"/>
      </material>
    </visual>

    <collision>
      <geometry>
          <cylinder radius="0.15" length="0.1"/>
      </geometry>
      <surface>
        <friction>
          <ode>
            <mu>0</mu>
            <mu2>0</mu2>
            <slip1>1.0</slip1>
            <slip2>1.0</slip2>
          </ode>
        </friction>
      </surface>
      <contact_coefficients mu="1" kp="1e+13" kd="1.0"/>
    </collision>
  </link>

  <joint name="wheel_left_joint" type="continuous">
    <origin xyz="0.2 -0.25 0.0" rpy="1.57 0.0 0.0"/>
    <parent link="base_footprint"/>
    <child link="wheel_left_link"/>
    <axis xyz="0.0 0.0 1.0"/>

  </joint>



  <link name="caster">
    <inertial>
            <mass value="1" />
            <inertia ixx="0.01" ixy="0.0" ixz="0" 
            iyy="0.01" iyz="0" izz="0.01" />
    </inertial>

    <visual>
    
      <geometry>
        <sphere radius=".08" />
      </geometry>
      <material name="white" />
    </visual>

    <collision>
      <geometry>
        <sphere radius=".08" />
      </geometry>
      <surface>
        <friction>
          <ode>
            <mu>0</mu>
            <mu2>0</mu2>
            <slip1>1.0</slip1>
            <slip2>1.0</slip2>
          </ode>
        </friction>
      </surface>
    </collision>
  </link>

  <joint name="caster_joint" type="continuous">
    <origin xyz="-0.3 0.0 -0.07" rpy="0.0 0.0 0.0"/>
    <axis xyz="0 0 1" />
    <parent link="base_footprint"/>
    <child link="caster"/>
  </joint>

  <!-- laser -->
  <link name="laser">
    <inertial>
            <mass value="1" />
            <inertia ixx="0.01" ixy="0.0" ixz="0" 
            iyy="0.01" iyz="0" izz="0.01" />
    </inertial>

    <visual>
    
      <geometry>
        <cylinder radius="0.05" length="0.05"/> 
       </geometry>
    </visual>

    <collision>
      <origin/>
      <geometry>
        <sphere radius=".08" />
      </geometry>
    </collision>
  </link>

  <joint name="laser_joint" type="fixed">
    <origin xyz="-0.32 0.0 0.08" rpy="0.0 0.0 3.14"/>
    <axis xyz="0 0 1" />
    <parent link="base_footprint"/>
    <child link="laser"/>
  </joint>



<!-- Gazebo colors to links as upper defined colors are only visible in RVIZ-->
<gazebo reference="base_footprint">
  <material>Gazebo/Orange</material>
</gazebo>
<gazebo reference="caster">
  <material>Gazebo/Black</material>
</gazebo>

<gazebo reference="wheel_right_link">
  <material>Gazebo/Blue</material>
</gazebo>
<gazebo reference="wheel_left_link">
  <material>Gazebo/Blue</material>
</gazebo> 
<!-- DIFFENERNTIAL DRIVEEEEEEEEEEEEE -->

<gazebo>
  <plugin name="differential_drive_controller"
          filename="libgazebo_ros_diff_drive.so">
      <leftJoint>wheel_left_joint</leftJoint>
      <rightJoint>wheel_right_joint</rightJoint>
      <legacyMode>false</legacyMode>
      
      <robotbase_footprintFrame>base_footprint_link</robotbase_footprintFrame>
      <wheelSeparation>0.25</wheelSeparation>
      <wheelDiameter>0.07</wheelDiameter>
      <publishWheelJointState>true</publishWheelJointState>
  </plugin>
</gazebo>
 <gazebo>
  <plugin name="joint_state_publisher"
          filename="libgazebo_ros_joint_state_publisher.so">
      <jointName>caster_joint</jointName>
  </plugin>
</gazebo>
  
<!-- laser plugin -->


<gazebo reference="laser">
  <sensor type="gpu_ray" name="laser">
      <pose>0 0 0 0 0 0</pose>
      <visualize>true</visualize>
      <update_rate>40</update_rate>
      <ray>
          <scan>
              <horizontal>
                  <samples>720</samples>
                  <resolution>1</resolution>
                  <min_angle>-1.578</min_angle>
                  <max_angle>1.578</max_angle>
              </horizontal>
          </scan>
          <range>
              <min>0.1</min>
              <max>30</max>
              <resolution>0.1</resolution>
          </range>
      </ray>
      <plugin name="gpu_laser" filename="libgazebo_ros_gpu_laser.so">
          <topicName>/scan</topicName>
          <frameName>laser</frameName>
      </plugin>
  </sensor>
</gazebo>

</robot>